---
title: "[250925] TIL"
excerpt: ""

categories:
  - TIL
tags:
  - [TIL]

permalink: /blog/til/250925

toc: true
toc_sticky: true

date: 2025-09-25
last_modified_at: 2025-09-25
---

# Today I Learned (2025-09-25)

- promise는 fulfilled , reject, pending 상태로 이루어져있음
- fulfilled 상태로 바뀌면 then에 등록된 콜백함수 실행

```js
async function foo() {
  await new Promise((r) => setTimeout(r, 1000));
  console.log("foo 끝");
}

async function baz() {
  foo(); // 대기 안 함
  foo(); // 대기 안 함
  console.log("baz 끝");
}

baz();

// baz 끝
// foo 끝
// foo 끝
```

# resolve 작업이 실패할 수도 있을까?

- resolve() 가 실패하는 상황은 발생하지 않음
- resolve() 는 promise를 fulfilled 로 만드는 함수이기 때문에, 성공적인 결과를 전달할 때 사용되며 실패 자체와는 관련이 없음
- 만약 promise 가 실패한다면, resolve 가 호출조차 되지 않고 reject() 가 호출됨
- 추가로, then()은 resolve()된 값을 처리하고, catch()는 reject()된 오류를 처리하는 식으로 Promise의 결과를 다루게 됩니다.
